Workbook

Sheet Lookups
A1: Region | B1: Channel | C1: Category | D1: Status | E1: Priority | F1: Department
A2: North | B2: Online | C2: Software | D2: Not Started | E2: Low | F2: Sales
A3: South | B3: Retail | C3: Hardware | D3: In Progress | E3: Medium | F3: Marketing
A4: East | B4: Partner | C4: Services | D4: Blocked | E4: High | F4: Finance
A5: West | B5: Wholesale | C5: Training | D5: Complete | E5: Critical | F5: Operations
A6: Central | C6: Support | F6: Engineering
F7: HR
F8: Support

Sheet Products
A1: Product ID | B1: Product Name | C1: Category | D1: Unit Price | E1: Unit Cost | F1: Launch Date | G1: Active
A2: P0001 | B2: Software Product 001 | C2: Software | D2: 54.39 | E2: 25.02 | F2: 44654 | G2: =TRUE() -> TRUE
A3: P0002 | B3: Software Product 002 | C3: Software | D3: 820.12 | E3: 579.72 | F3: 44375 | G3: =FALSE() -> FALSE
A4: P0003 | B4: Software Product 003 | C4: Software | D4: 60.01 | E4: 26.25 | F4: 45231 | G4: =TRUE() -> TRUE
A5: P0004 | B5: Support Product 004 | C5: Support | D5: 258.63 | E5: 157.75 | F5: 45313 | G5: =FALSE() -> FALSE
A6: P0005 | B6: Hardware Product 005 | C6: Hardware | D6: 552.82 | E6: 255 | F6: 45977 | G6: =TRUE() -> TRUE
A7: P0006 | B7: Hardware Product 006 | C7: Hardware | D7: 845.31 | E7: 410.91 | F7: 44515 | G7: =TRUE() -> TRUE
A8: P0007 | B8: Services Product 007 | C8: Services | D8: 145.1 | E8: 72.84 | F8: 44932 | G8: =TRUE() -> TRUE
A9: P0008 | B9: Support Product 008 | C9: Support | D9: 335.81 | E9: 123.37 | F9: 45137 | G9: =TRUE() -> TRUE
A10: P0009 | B10: Training Product 009 | C10: Training | D10: 117.59 | E10: 54.95 | F10: 45484 | G10: =TRUE() -> TRUE
A11: P0010 | B11: Support Product 010 | C11: Support | D11: 250.94 | E11: 94.81 | F11: 45551 | G11: =TRUE() -> TRUE
A12: P0011 | B12: Services Product 011 | C12: Services | D12: 1182.64 | E12: 818.54 | F12: 45971 | G12: =TRUE() -> TRUE
A13: P0012 | B13: Training Product 012 | C13: Training | D13: 351.62 | E13: 212.47 | F13: 44944 | G13: =TRUE() -> TRUE
A14: P0013 | B14: Services Product 013 | C14: Services | D14: 442.44 | E14: 273.46 | F14: 45634 | G14: =TRUE() -> TRUE
A15: P0014 | B15: Support Product 014 | C15: Support | D15: 771.1 | E15: 434.64 | F15: 44698 | G15: =TRUE() -> TRUE
A16: P0015 | B16: Training Product 015 | C16: Training | D16: 470.86 | E16: 351.17 | F16: 45507 | G16: =TRUE() -> TRUE
A17: P0016 | B17: Services Product 016 | C17: Services | D17: 1015.35 | E17: 670.54 | F17: 44666 | G17: =TRUE() -> TRUE
A18: P0017 | B18: Services Product 017 | C18: Services | D18: 496.37 | E18: 186.87 | F18: 45358 | G18: =TRUE() -> TRUE
A19: P0018 | B19: Hardware Product 018 | C19: Hardware | D19: 795.14 | E19: 404.13 | F19: 45513 | G19: =FALSE() -> FALSE
A20: P0019 | B20: Hardware Product 019 | C20: Hardware | D20: 336.23 | E20: 150.85 | F20: 45346 | G20: =TRUE() -> TRUE
A21: P0020 | B21: Support Product 020 | C21: Support | D21: 528.41 | E21: 308.28 | F21: 44938 | G21: =TRUE() -> TRUE
A22: P0021 | B22: Hardware Product 021 | C22: Hardware | D22: 623.69 | E22: 240.97 | F22: 44293 | G22: =TRUE() -> TRUE
A23: P0022 | B23: Hardware Product 022 | C23: Hardware | D23: 762.25 | E23: 508.29 | F23: 45061 | G23: =TRUE() -> TRUE
A24: P0023 | B24: Training Product 023 | C24: Training | D24: 473.4 | E24: 354.32 | F24: 45280 | G24: =TRUE() -> TRUE
A25: P0024 | B25: Support Product 024 | C25: Support | D25: 1036.42 | E25: 367.51 | F25: 45673 | G25: =TRUE() -> TRUE
A26: P0025 | B26: Support Product 025 | C26: Support | D26: 907.28 | E26: 596.48 | F26: 44893 | G26: =TRUE() -> TRUE
A27: P0026 | B27: Services Product 026 | C27: Services | D27: 535.85 | E27: 284.8 | F27: 45675 | G27: =TRUE() -> TRUE
A28: P0027 | B28: Support Product 027 | C28: Support | D28: 920.31 | E28: 509 | F28: 44414 | G28: =TRUE() -> TRUE
A29: P0028 | B29: Support Product 028 | C29: Support | D29: 740.54 | E29: 304.46 | F29: 45758 | G29: =TRUE() -> TRUE
A30: P0029 | B30: Support Product 029 | C30: Support | D30: 1145.36 | E30: 823.48 | F30: 44198 | G30: =TRUE() -> TRUE
A31: P0030 | B31: Training Product 030 | C31: Training | D31: 47.89 | E31: 34.56 | F31: 45996 | G31: =TRUE() -> TRUE
... A35: P0034 | B35: Support Product 034 | C35: Support | D35: 1050.11 | E35: 545.28 | F35: 44630 | G35: =TRUE() -> TRUE
A36: P0035 | B36: Services Product 035 | C36: Services | D36: 493.82 | E36: 305.51 | F36: 44961 | G36: =FALSE() -> FALSE
A37: P0036 | B37: Support Product 036 | C37: Support | D37: 555.5 | E37: 249.51 | F37: 44328 | G37: =TRUE() -> TRUE
A38: P0037 | B38: Software Product 037 | C38: Software | D38: 716.26 | E38: 316.62 | F38: 44648 | G38: =TRUE() -> TRUE
A39: P0038 | B39: Software Product 038 | C39: Software | D39: 856.71 | E39: 320.02 | F39: 44335 | G39: =TRUE() -> TRUE
A40: P0039 | B40: Services Product 039 | C40: Services | D40: 108.26 | E40: 48.2 | F40: 45567 | G40: =FALSE() -> FALSE
A41: P0040 | B41: Hardware Product 040 | C41: Hardware | D41: 658.6 | E41: 421.07 | F41: 45366 | G41: =FALSE() -> FALSE
A42: P0041 | B42: Hardware Product 041 | C42: Hardware | D42: 946.93 | E42: 637.28 | F42: 44586 | G42: =TRUE() -> TRUE
A43: P0042 | B43: Software Product 042 | C43: Software | D43: 799.3 | E43: 393.03 | F43: 45038 | G43: =FALSE() -> FALSE
...

Sheet Customers
A1: Customer ID | B1: Customer Name | C1: Region | D1: Segment | E1: Signup Date | F1: Account Manager | G1: Risk Score
A2: C00001 | B2: Customer 0001 | C2: South | D2: Mid-Market | E2: 46006 | F2: Manager 7 | G2: 57
A3: C00002 | B3: Customer 0002 | C3: South | D3: Mid-Market | E3: 44548 | F3: Manager 2 | G3: 61.3
A4: C00003 | B4: Customer 0003 | C4: West | D4: Mid-Market | E4: 45869 | F4: Manager 15 | G4: 58.7
A5: C00004 | B5: Customer 0004 | C5: South | D5: Public Sector | E5: 44871 | F5: Manager 8 | G5: 26.3
A6: C00005 | B6: Customer 0005 | C6: North | D6: Public Sector | E6: 45009 | F6: Manager 11 | G6: 55.1
A7: C00006 | B7: Customer 0006 | C7: North | D7: Public Sector | E7: 45246 | F7: Manager 10 | G7: 30.6
A8: C00007 | B8: Customer 0007 | C8: West | D8: Enterprise | E8: 45702 | F8: Manager 14 | G8: 30.9
A9: C00008 | B9: Customer 0008 | C9: West | D9: Public Sector | E9: 44267 | F9: Manager 4 | G9: 38.8
A10: C00009 | B10: Customer 0009 | C10: East | D10: Enterprise | E10: 45040 | F10: Manager 1 | G10: 97.8
A11: C00010 | B11: Customer 0010 | C11: West | D11: Enterprise | E11: 43864 | F11: Manager 10 | G11: 86.6
A12: C00011 | B12: Customer 0011 | C12: North | D12: Public Sector | E12: 45003 | F12: Manager 13 | G12: 80.1
A13: C00012 | B13: Customer 0012 | C13: Central | D13: Enterprise | E13: 44728 | F13: Manager 11 | G13: 19.8
... A501: C00500 | B501: Customer 0500 | C501: South | D501: Mid-Market | E501: 43838 | F501: Manager 12 | G501: 94.9

Sheet Sales
A1: Order ID | B1: Order Date | C1: Customer ID | D1: Product ID | E1: Region | F1: Channel | G1: Quantity | H1: Unit Price | I1: Unit Cost | J1: Discount | K1: Revenue | L1: Profit
A2: O000001 | B2: 45325 | C2: C00436 | D2: P0101 | E2: West | F2: Retail | G2: 25 | H2: 679.95 | I2: 487.52 | J2: 0.08 | K2: =G2*H2*(1-J2) -> 15638.85 | L2: =K2-(G2*I2) -> 3450.85
A3: O000002 | B3: 45946 | C3: C00163 | D3: P0155 | E3: East | F3: Online | G3: 20 | H3: 471.94 | I3: 336.68 | J3: 0 | K3: =G3*H3*(1-J3) -> 9438.8 | L3: =K3-(G3*I3) -> 2705.2
A4: O000003 | B4: 45371 | C4: C00073 | D4: P0128 | E4: North | F4: Retail | G4: 11 | H4: 1024.09 | I4: 604.38 | J4: 0.1 | K4: =G4*H4*(1-J4) -> 10138.491 | L4: =K4-(G4*I4) -> 3490.311
A5: O000004 | B5: 46198 | C5: C00164 | D5: P0089 | E5: South | F5: Online | G5: 6 | H5: 497.82 | I5: 233.11 | J5: 0.1 | K5: =G5*H5*(1-J5) -> 2688.228 | L5: =K5-(G5*I5) -> 1289.568
A6: O000005 | B6: 46199 | C6: C00344 | D6: P0182 | E6: West | F6: Partner | G6: 21 | H6: 311.38 | I6: 177.64 | J6: 0.1 | K6: =G6*H6*(1-J6) -> 5885.082 | L6: =K6-(G6*I6) -> 2154.642
A7: O000006 | B7: 45547 | C7: C00006 | D7: P0115 | E7: North | F7: Online | G7: 9 | H7: 1105.46 | I7: 820.57 | J7: 0 | K7: =G7*H7*(1-J7) -> 9949.14 | L7: =K7-(G7*I7) -> 2564.01
A8: O000007 | B8: 45293 | C8: C00132 | D8: P0090 | E8: Central | F8: Online | G8: 4 | H8: 806.29 | I8: 404.48 | J8: 0.1 | K8: =G8*H8*(1-J8) -> 2902.644 | L8: =K8-(G8*I8) -> 1284.724
A9: O000008 | B9: 45462 | C9: C00225 | D9: P0099 | E9: West | F9: Wholesale | G9: 24 | H9: 198.4 | I9: 124.01 | J9: 0.05 | K9: =G9*H9*(1-J9) -> 4523.52 | L9: =K9-(G9*I9) -> 1547.28
A10: O000009 | B10: 45851 | C10: C00452 | D10: P0127 | E10: South | F10: Wholesale | G10: 13 | H10: 720.71 | I10: 491.69 | J10: 0.02 | K10: =G10*H10*(1-J10) -> 9181.8454 | L10: =K10-(G10*I10) -> 2789.8754
A11: O000010 | B11: 46176 | C11: C00425 | D11: P0026 | E11: East | F11: Retail | G11: 16 | H11: 535.85 | I11: 284.8 | J11: 0.15 | K11: =G11*H11*(1-J11) -> 7287.56 | L11: =K11-(G11*I11) -> 2730.76
A12: O000011 | B12: 46158 | C12: C00232 | D12: P0042 | E12: Central | F12: Online | G12: 3 | H12: 799.3 | I12: 393.03 | J12: 0.15 | K12: =G12*H12*(1-J12) -> 2038.215 | L12: =K12-(G12*I12) -> 859.125
A13: O000012 | B13: 45399 | C13: C00011 | D13: P0076 | E13: North | F13: Online | G13: 11 | H13: 1040.91 | I13: 770.78 | J13: 0.02 | K13: =G13*H13*(1-J13) -> 11221.01 | L13: =K13-(G13*I13) -> 2742.4298
... A1001: O001000 | B1001: 46190 | C1001: C00394 | D1001: P0091 | E1001: West | F1001: Partner | G1001: 2 | H1001: 693.7 | I1001: 355.47 | J1001: 0.15 | K1001: =G1001*H1001*(1-J1001) -> 1179.29 | L1001: =K1001-(G1001*I1001) -> 468.35

Sheet Inventory
A1: SKU | B1: Product ID | C1: Warehouse | D1: On Hand | E1: Reorder Point | F1: Unit Cost | G1: Inventory Value | H1: Status
A2: SKU00001 | B2: P0039 | C2: ATL | D2: 527 | E2: 76 | F2: 48.2 | G2: =D2*F2 -> 25401.4 | H2: OK
A3: SKU00002 | B3: P0113 | C3: ATL | D3: 468 | E3: 78 | F3: 148.29 | G3: =D3*F3 -> 69399.72 | H3: OK
A4: SKU00003 | B4: P0157 | C4: SEA | D4: 104 | E4: 60 | F4: 346.44 | G4: =D4*F4 -> 36029.76 | H4: OK
A5: SKU00004 | B5: P0027 | C5: DAL | D5: 171 | E5: 80 | F5: 509 | G5: =D5*F5 -> 87039 | H5: OK
A6: SKU00005 | B6: P0093 | C6: NYC | D6: 160 | E6: 124 | F6: 337.48 | G6: =D6*F6 -> 53996.8 | H6: OK
A7: SKU00006 | B7: P0196 | C7: ATL | D7: 518 | E7: 177 | F7: 536.83 | G7: =D7*F7 -> 278077.94 | H7: OK
A8: SKU00007 | B8: P0040 | C8: DAL | D8: 372 | E8: 135 | F8: 421.07 | G8: =D8*F8 -> 156638.04 | H8: OK
A9: SKU00008 | B9: P0032 | C9: NYC | D9: 206 | E9: 162 | F9: 729.21 | G9: =D9*F9 -> 150217.26 | H9: OK
A10: SKU00009 | B10: P0197 | C10: NYC | D10: 6 | E10: 112 | F10: 63.49 | G10: =D10*F10 -> 380.94 | H10: Reorder
A11: SKU00010 | B11: P0088 | C11: DAL | D11: 293 | E11: 179 | F11: 409.35 | G11: =D11*F11 -> 119939.55 | H11: OK
A12: SKU00011 | B12: P0022 | C12: NYC | D12: 272 | E12: 145 | F12: 508.29 | G12: =D12*F12 -> 138254.88 | H12: OK
A13: SKU00012 | B13: P0093 | C13: SEA | D13: 251 | E13: 88 | F13: 337.48 | G13: =D13*F13 -> 84707.48 | H13: OK
... A501: SKU00500 | B501: P0182 | C501: DAL | D501: 203 | E501: 78 | F501: 177.64 | G501: =D501*F501 -> 36060.92 | H501: OK

Sheet Employees
A1: Employee ID | B1: Name | C1: Department | D1: Role | E1: Manager | F1: Hire Date | G1: Salary | H1: Performance Rating | I1: Location
A2: E0001 | B2: Employee 001 | C2: Finance | D2: Analyst | E2: Manager 3 | F2: 44352 | G2: 110188 | H2: 4.4 | I2: New York
A3: E0002 | B3: Employee 002 | C3: Marketing | D3: Specialist | E3: Manager 4 | F3: 44699 | G3: 142194 | H3: 5 | I3: New York
A4: E0003 | B4: Employee 003 | C4: Operations | D4: Senior Manager | E4: Manager 9 | F4: 44765 | G4: 159834 | H4: 4.2 | I4: Chicago
A5: E0004 | B5: Employee 004 | C5: Finance | D5: Senior Manager | E5: Manager 9 | F5: 45709 | G5: 176053 | H5: 4.4 | I5: Seattle
A6: E0005 | B6: Employee 005 | C6: Marketing | D6: Analyst | E6: Manager 2 | F6: 45982 | G6: 57772 | H6: 2.8 | I6: Austin
A7: E0006 | B7: Employee 006 | C7: Engineering | D7: Analyst | E7: Manager 13 | F7: 45539 | G7: 85999 | H7: 2.6 | I7: Austin
A8: E0007 | B8: Employee 007 | C8: Operations | D8: Director | E8: Manager 12 | F8: 42768 | G8: 111928 | H8: 3.7 | I8: Austin
A9: E0008 | B9: Employee 008 | C9: Operations | D9: Analyst | E9: Manager 13 | F9: 44492 | G9: 87472 | H9: 4 | I9: Remote
A10: E0009 | B10: Employee 009 | C10: Marketing | D10: Associate | E10: Manager 5 | F10: 45876 | G10: 70075 | H10: 4.7 | I10: Chicago
A11: E0010 | B11: Employee 010 | C11: HR | D11: Senior Manager | E11: Manager 4 | F11: 44677 | G11: 147597 | H11: 4.5 | I11: New York
A12: E0011 | B12: Employee 011 | C12: HR | D12: Specialist | E12: Manager 9 | F12: 45239 | G12: 78748 | H12: 3 | I12: Remote
A13: E0012 | B13: Employee 012 | C13: HR | D13: Specialist | E13: Manager 3 | F13: 43675 | G13: 70789 | H13: 2.8 | I13: New York
... A251: E0250 | B251: Employee 250 | C251: Engineering | D251: Manager | E251: Manager 5 | F251: 43187 | G251: 56092 | H251: 3.7 | I251: Chicago

Sheet Projects
A1: Project ID | B1: Project Name | C1: Department | D1: Owner | E1: Priority | F1: Status | G1: Start Date | H1: Due Date | I1: Budget | J1: Spend | K1: Variance | L1: Completion %
A2: PRJ0001 | B2: Project 001 | C2: Finance | D2: Manager 10 | E2: Medium | F2: Blocked | G2: 45896 | H2: 46100 | I2: 88762 | J2: 59959.16 | K2: =I2-J2 -> 28802.84 | L2: 0.62
A3: PRJ0002 | B3: Project 002 | C3: Operations | D3: Manager 1 | E3: Medium | F3: Blocked | G3: 45805 | H3: 45851 | I3: 429317 | J3: 182116.01 | K3: =I3-J3 -> 247200.99 | L3: 0.75
A4: PRJ0003 | B4: Project 003 | C4: Operations | D4: Manager 6 | E4: Low | F4: Not Started | G4: 45721 | H4: 45764 | I4: 266044 | J4: 116102.57 | K4: =I4-J4 -> 149941.43 | L4: 0.32
A5: PRJ0004 | B5: Project 004 | C5: Support | D5: Manager 9 | E5: Medium | F5: Not Started | G5: 45728 | H5: 45847 | I5: 470703 | J5: 193737.63 | K5: =I5-J5 -> 276965.37 | L5: 0.91
A6: PRJ0005 | B6: Project 005 | C6: Engineering | D6: Manager 15 | E6: Low | F6: Blocked | G6: 45796 | H6: 45862 | I6: 394330 | J6: 124766.07 | K6: =I6-J6 -> 269563.93 | L6: 0.28
A7: PRJ0006 | B7: Project 006 | C7: Support | D7: Manager 11 | E7: Critical | F7: Complete | G7: 45674 | H7: 45825 | I7: 499126 | J7: 244619.39 | K7: =I7-J7 -> 254506.61 | L7: 0.51
A8: PRJ0007 | B8: Project 007 | C8: Finance | D8: Manager 10 | E8: High | F8: In Progress | G8: 46153 | H8: 46208 | I8: 478206 | J8: 185250.79 | K8: =I8-J8 -> 292955.21 | L8: 0.72
A9: PRJ0008 | B9: Project 008 | C9: Engineering | D9: Manager 3 | E9: Medium | F9: Blocked | G9: 45881 | H9: 46084 | I9: 469240 | J9: 213376.52 | K9: =I9-J9 -> 255863.48 | L9: 0.17
A10: PRJ0009 | B10: Project 009 | C10: Sales | D10: Manager 5 | E10: Critical | F10: In Progress | G10: 45871 | H10: 46042 | I10: 114607 | J10: 49414.93 | K10: =I10-J10 -> 65192.07 | L10: 0.48
A11: PRJ0010 | B11: Project 010 | C11: Operations | D11: Manager 12 | E11: High | F11: Blocked | G11: 46058 | H11: 46199 | I11: 60353 | J11: 15237.37 | K11: =I11-J11 -> 45115.63 | L11: 0.59
A12: PRJ0011 | B12: Project 011 | C12: Operations | D12: Manager 8 | E12: Low | F12: Not Started | G12: 45839 | H12: 45978 | I12: 254607 | J12: 143230.75 | K12: =I12-J12 -> 111376.25 | L12: 0.98
A13: PRJ0012 | B13: Project 012 | C13: Finance | D13: Manager 13 | E13: Medium | F13: Blocked | G13: 45873 | H13: 45925 | I13: 406286 | J13: 103458.35 | K13: =I13-J13 -> 302827.65 | L13: 0.16
... A201: PRJ0200 | B201: Project 200 | C201: Marketing | D201: Manager 4 | E201: Medium | F201: Blocked | G201: 45860 | H201: 45932 | I201: 251480 | J201: 25381.26 | K201: =I201-J201 -> 226098.74 | L201: 0.39

Sheet Support Tickets
A1: Ticket ID | B1: Created Date | C1: Customer ID | D1: Category | E1: Priority | F1: Status | G1: Assigned To | H1: First Response Hrs | I1: Resolution Hrs | J1: Satisfaction
A2: T000001 | B2: 45899 | C2: C00440 | D2: Technical | E2: Low | F2: Pending | G2: Employee 112 | H2: 2.3 | I2: 60.2 | J2: 5
A3: T000002 | B3: 46146 | C3: C00082 | D3: Access | E3: High | F3: Open | G3: Employee 026 | H3: 11.4 | I3: 165.5 | J3: 2
A4: T000003 | B4: 46132 | C4: C00362 | D4: Technical | E4: Critical | F4: Closed | G4: Employee 196 | H4: 22 | I4: 94.2 | J4: 3
A5: T000004 | B5: 45992 | C5: C00460 | D5: Access | E5: Medium | F5: Closed | G5: Employee 210 | H5: 16.2 | I5: 209.7 | J5: 5
A6: T000005 | B6: 46013 | C6: C00251 | D6: Feature Request | E6: Critical | F6: Open | G6: Employee 007 | H6: 5.4 | I6: 146.8 | J6: 2
A7: T000006 | B7: 46006 | C7: C00257 | D7: Billing | E7: High | F7: Resolved | G7: Employee 157 | H7: 14.4 | I7: 96.8 | J7: 1
A8: T000007 | B8: 46169 | C8: C00097 | D8: Billing | E8: Medium | F8: Pending | G8: Employee 055 | H8: 7.3 | I8: 24.1 | J8: 4
A9: T000008 | B9: 45812 | C9: C00146 | D9: Access | E9: Medium | F9: Closed | G9: Employee 100 | H9: 16.2 | I9: 116.4 | J9: 3
A10: T000009 | B10: 45825 | C10: C00204 | D10: Feature Request | E10: Critical | F10: Pending | G10: Employee 214 | H10: 2.6 | I10: 193.9 | J10: 3
A11: T000010 | B11: 45670 | C11: C00083 | D11: Access | E11: Low | F11: Closed | G11: Employee 033 | H11: 13.8 | I11: 93.4 | J11: 4
A12: T000011 | B12: 46069 | C12: C00217 | D12: Billing | E12: Low | F12: Closed | G12: Employee 078 | H12: 10.3 | I12: 178.6 | J12: 1
A13: T000012 | B13: 46142 | C13: C00365 | D13: Access | E13: Critical | F13: Resolved | G13: Employee 217 | H13: 12.9 | I13: 88.8 | J13: 2
... A701: T000700 | B701: 46130 | C701: C00427 | D701: Feature Request | E701: Low | F701: Closed | G701: Employee 038 | H701: 2.4 | I701: 20.9 | J701: 3

Sheet Marketing
A1: Date | B1: Campaign | C1: Channel | D1: Spend | E1: Leads | F1: Conversions | G1: Cost / Lead | H1: Conversion Rate
A2: 45839 | B2: Webinar | C2: Display | D2: 2215.07 | E2: 127 | F2: 57 | G2: =IFERROR(D2/E2,0) -> 17.441496 | H2: =IFERROR(F2/E2,0) -> 0.4488189
A3: 45840 | B3: Retargeting | C3: Email | D3: 1127.36 | E3: 423 | F3: 320 | G3: =IFERROR(D3/E3,0) -> 2.6651537 | H3: =IFERROR(F3/E3,0) -> 0.75650118
A4: 45841 | B4: Partner Push | C4: Social | D4: 2843.1 | E4: 651 | F4: 551 | G4: =IFERROR(D4/E4,0) -> 4.3672811 | H4: =IFERROR(F4/E4,0) -> 0.84639017
A5: 45842 | B5: Partner Push | C5: Display | D5: 3569.68 | E5: 615 | F5: 405 | G5: =IFERROR(D5/E5,0) -> 5.8043577 | H5: =IFERROR(F5/E5,0) -> 0.65853659
A6: 45843 | B6: Partner Push | C6: Email | D6: 2341.65 | E6: 538 | F6: 390 | G6: =IFERROR(D6/E6,0) -> 4.3525093 | H6: =IFERROR(F6/E6,0) -> 0.72490706
A7: 45844 | B7: Webinar | C7: Display | D7: 3521.27 | E7: 112 | F7: 41 | G7: =IFERROR(D7/E7,0) -> 31.439911 | H7: =IFERROR(F7/E7,0) -> 0.36607143
A8: 45845 | B8: Brand Awareness | C8: Search | D8: 1490.79 | E8: 341 | F8: 337 | G8: =IFERROR(D8/E8,0) -> 4.3718182 | H8: =IFERROR(F8/E8,0) -> 0.98826979
A9: 45846 | B9: Demand Gen | C9: Search | D9: 839.55 | E9: 158 | F9: 153 | G9: =IFERROR(D9/E9,0) -> 5.3136076 | H9: =IFERROR(F9/E9,0) -> 0.96835443
A10: 45847 | B10: Webinar | C10: Social | D10: 4262.89 | E10: 509 | F10: 509 | G10: =IFERROR(D10/E10,0) -> 8.3750295 | H10: =IFERROR(F10/E10,0) -> 1
A11: 45848 | B11: Brand Awareness | C11: Email | D11: 3560.71 | E11: 410 | F11: 355 | G11: =IFERROR(D11/E11,0) -> 8.6846585 | H11: =IFERROR(F11/E11,0) -> 0.86585366
A12: 45849 | B12: Retargeting | C12: Search | D12: 788.6 | E12: 505 | F12: 40 | G12: =IFERROR(D12/E12,0) -> 1.5615842 | H12: =IFERROR(F12/E12,0) -> 0.079207921
A13: 45850 | B13: Partner Push | C13: Events | D13: 1328.58 | E13: 630 | F13: 550 | G13: =IFERROR(D13/E13,0) -> 2.1088571 | H13: =IFERROR(F13/E13,0) -> 0.87301587
... A366: 46203 | B366: Webinar | C366: Search | D366: 3712.58 | E366: 111 | F366: 19 | G366: =IFERROR(D366/E366,0) -> 33.446667 | H366: =IFERROR(F366/E366,0) -> 0.17117117

Sheet Finance Monthly
A1: Month | B1: Revenue | C1: COGS | D1: Gross Profit | E1: Operating Expense | F1: EBITDA | G1: Cash Balance
A2: 45292 | B2: 494080.08 | C2: 252698.14 | D2: =B2-C2 -> 241381.94 | E2: 160075.91 | F2: =D2-E2 -> 81306.03 | G2: 989499.47
A3: 45323 | B3: 506663.49 | C3: 245511.59 | D3: =B3-C3 -> 261151.9 | E3: 155779.21 | F3: =D3-E3 -> 105372.69 | G3: 1057089.9
A4: 45352 | B4: 464598.34 | C4: 237234.67 | D4: =B4-C4 -> 227363.67 | E4: 159928.79 | F4: =D4-E4 -> 67434.88 | G4: 1027342.9
A5: 45383 | B5: 452497.37 | C5: 225564.47 | D5: =B5-C5 -> 226932.9 | E5: 162854.91 | F5: =D5-E5 -> 64077.99 | G5: 1041985.4
A6: 45413 | B6: 508194.21 | C6: 276091.04 | D6: =B6-C6 -> 232103.17 | E6: 153274.06 | F6: =D6-E6 -> 78829.11 | G6: 1162805.1
A7: 45444 | B7: 527495.01 | C7: 223937.95 | D7: =B7-C7 -> 303557.06 | E7: 190865.75 | F7: =D7-E7 -> 112691.31 | G7: 1204317.9
A8: 45474 | B8: 568383.47 | C8: 287353.33 | D8: =B8-C8 -> 281030.14 | E8: 176006.17 | F8: =D8-E8 -> 105023.97 | G8: 1216704.5
A9: 45505 | B9: 519241.69 | C9: 287922.43 | D9: =B9-C9 -> 231319.26 | E9: 198938.78 | F9: =D9-E9 -> 32380.48 | G9: 1311105.7
A10: 45536 | B10: 564493.78 | C10: 318384.36 | D10: =B10-C10 -> 246109.42 | E10: 193931.34 | F10: =D10-E10 -> 52178.08 | G10: 1251315.1
A11: 45566 | B11: 519528.81 | C11: 225824.25 | D11: =B11-C11 -> 293704.56 | E11: 201298.54 | F11: =D11-E11 -> 92406.02 | G11: 1289322.4
A12: 45597 | B12: 538837.61 | C12: 308543.84 | D12: =B12-C12 -> 230293.77 | E12: 201884.54 | F12: =D12-E12 -> 28409.23 | G12: 1392845.7
A13: 45627 | B13: 595693.42 | C13: 267508.19 | D13: =B13-C13 -> 328185.23 | E13: 184487.57 | F13: =D13-E13 -> 143697.66 | G13: 1316852.1
... A37: 46357 | B37: 842641.5 | C37: 472677.06 | D37: =B37-C37 -> 369964.44 | E37: 322582.94 | F37: =D37-E37 -> 47381.5 | G37: 2189569.1

Sheet Operations
A1: Date | B1: Facility | C1: Shift | D1: Units Produced | E1: Defects | F1: Defect Rate | G1: Downtime Minutes | H1: Labor Hours
A2: 45833 | B2: Plant B | C2: Day | D2: 5107 | E2: 287 | F2: =IFERROR(E2/D2,0) -> 0.056197376 | G2: 12 | H2: 206.1
A3: 45789 | B3: Plant D | C3: Night | D3: 4900 | E3: 215 | F3: =IFERROR(E3/D3,0) -> 0.043877551 | G3: 239 | H3: 101.2
A4: 45934 | B4: Plant A | C4: Day | D4: 5167 | E4: 267 | F4: =IFERROR(E4/D4,0) -> 0.051674086 | G4: 40 | H4: 69
A5: 46114 | B5: Plant B | C5: Day | D5: 865 | E5: 48 | F5: =IFERROR(E5/D5,0) -> 0.055491329 | G5: 176 | H5: 88.5
A6: 46148 | B6: Plant C | C6: Swing | D6: 4721 | E6: 22 | F6: =IFERROR(E6/D6,0) -> 0.0046600297 | G6: 230 | H6: 278.5
A7: 45951 | B7: Plant D | C7: Swing | D7: 3648 | E7: 49 | F7: =IFERROR(E7/D7,0) -> 0.013432018 | G7: 86 | H7: 172.3
A8: 45786 | B8: Plant A | C8: Day | D8: 1880 | E8: 109 | F8: =IFERROR(E8/D8,0) -> 0.057978723 | G8: 2 | H8: 52
A9: 46101 | B9: Plant C | C9: Swing | D9: 3078 | E9: 145 | F9: =IFERROR(E9/D9,0) -> 0.047108512 | G9: 237 | H9: 57.9
A10: 45713 | B10: Plant A | C10: Day | D10: 2630 | E10: 145 | F10: =IFERROR(E10/D10,0) -> 0.05513308 | G10: 229 | H10: 246.4
A11: 45797 | B11: Plant A | C11: Day | D11: 3714 | E11: 27 | F11: =IFERROR(E11/D11,0) -> 0.00726979 | G11: 187 | H11: 281.9
A12: 46022 | B12: Plant D | C12: Day | D12: 3530 | E12: 100 | F12: =IFERROR(E12/D12,0) -> 0.028328612 | G12: 84 | H12: 203.1
A13: 46098 | B13: Plant A | C13: Night | D13: 4661 | E13: 1 | F13: =IFERROR(E13/D13,0) -> 0.00021454623 | G13: 156 | H13: 101.2
... A501: 45963 | B501: Plant A | C501: Swing | D501: 2078 | E501: 52 | F501: =IFERROR(E501/D501,0) -> 0.025024062 | G501: 225 | H501: 53.4

Sheet Dashboard
A1: Executive Dashboard
A3: Metric | B3: Value | D3: Region | E3: Revenue
A4: Total Revenue | B4: =SUM(Sales!K2:K1001) -> 8142324.2 | D4: North | E4: =SUMIF(Sales!E:E,D4,Sales!K:K) -> 1640577.7
A5: Total Profit | B5: =SUM(Sales!L2:L1001) -> 3233537.6 | D5: South | E5: =SUMIF(Sales!E:E,D5,Sales!K:K) -> 1471191.3
A6: Gross Margin | B6: =IFERROR(B5/B4,0) -> 0.3971271 | D6: East | E6: =SUMIF(Sales!E:E,D6,Sales!K:K) -> 1972546.6
A7: Open Projects | B7: =COUNTIF(Projects!F2:F201,"<>Complete") -> 151 | D7: West | E7: =SUMIF(Sales!E:E,D7,Sales!K:K) -> 1563424.2
A8: Open Tickets | B8: =COUNTIF('Support Tickets'!F2:F701,"Open")+COUNTIF('Support Tickets'!F2:F701,"Pending") -> 353 | D8: Central | E8: =SUMIF(Sales!E:E,D8,Sales!K:K) -> 1494584.5
A9: Inventory Reorder SKUs | B9: =COUNTIF(Inventory!H2:H501,"Reorder") -> 93
A10: Avg Satisfaction | B10: =AVERAGE('Support Tickets'!J2:J701) -> 3.0257143
A12: Priority | B12: Projects | C12: Tickets
A13: Low | B13: =COUNTIF(Projects!E:E,A13) -> 45 | C13: =COUNTIF('Support Tickets'!E:E,A13) -> 189
A14: Medium | B14: =COUNTIF(Projects!E:E,A14) -> 57 | C14: =COUNTIF('Support Tickets'!E:E,A14) -> 173
A15: High | B15: =COUNTIF(Projects!E:E,A15) -> 35 | C15: =COUNTIF('Support Tickets'!E:E,A15) -> 155
A16: Critical | B16: =COUNTIF(Projects!E:E,A16) -> 63 | C16: =COUNTIF('Support Tickets'!E:E,A16) -> 183
A17: Total | B17: =SUM(B13:B16) -> 200 | C17: =SUM(C13:C16) -> 700

Sheet README
A1: Workbook Overview
A3: Sheet | B3: Purpose | C3: Rows | D3: Notes
A4: Dashboard | B4: KPI summary and charts | C4: n/a | D4: Formula-driven from source tabs
A5: Sales | B5: Orders with revenue/profit formulas | C5: 1,000 | D5: Includes data validation and conditional formatting
A6: Customers | B6: Customer master data | C6: 500 | D6: Segments, regions, account managers
A7: Products | B7: Product master data | C7: 200 | D7: Pricing and cost basis
A8: Inventory | B8: SKU inventory position | C8: 500 | D8: Reorder status and inventory value formula
A9: Employees | B9: Employee roster | C9: 250 | D9: Department and performance details
A10: Projects | B10: Project portfolio | C10: 200 | D10: Budget, spend, variance formulas
A11: Support Tickets | B11: Customer support workload | C11: 700 | D11: Priority, status, satisfaction
A12: Marketing | B12: Daily campaign performance | C12: 365 | D12: Cost per lead and conversion rate formulas
A13: Finance Monthly | B13: Monthly P&L and cash balance | C13: 36 | D13: Gross profit and EBITDA formulas
A14: Operations | B14: Facility production metrics | C14: 500 | D14: Defect rate formula
A15: Lookups | B15: Dropdown source lists | C15: n/a | D15: Used for validations
